Workbook

Sheet Cover
A1: BFS INFORMATION SECURITY MANAGEMENT SYSTEM
A5: INFORMATION SECURITY RISK REGISTER
A11: Comprehensive Information Security Risk Register Aligned with BFS-ISMS-003 Risk Assessment and Treatment Methodology
B16: Reference | D16: BFS-RR-2025
B17: Version | D17: 1.0
B18: Classification | D18: CONFIDENTIAL — Authorized Use Only
B19: Effective Date | D19: April 2025
B20: Review Cycle | D20: Per Risk Level (Monthly CRITICAL / Quarterly HIGH / Semi-annually MEDIUM / Annually LOW)
B21: Methodology Reference | D21: BFS-ISMS-003 Risk Assessment and Treatment Methodology
B22: Companion Documents | D22: BFS-ISMS-001 (Top-Level Policy); BFS-ISMS-002 (Scope and Context); BFS-ISMS-004 (Statement of Applicability); BFS-ISP series (Implementation)
B23: Framework Alignment | D23: ISO/IEC 27001:2022 Clauses 6.1.2 and 6.1.3; ISO/IEC 27005:2022; ISO 31000:2018; NIST SP 800-30
B24: Regulatory Alignment | D24: BSP Circular 1140; BSP Circular 1048; RA 10173; RA 11765; PCI DSS v4.0
B25: Owner | D25: Chief Information Security Officer / Chief Risk Officer
B26: Maintainer | D26: CISO Office / Risk Management Team
B27: Total Risks | D27: 45
B28: Approval | D28: CISO + CIO + CRO + Board Audit & Risk Committee
A32: © BFS Financial Services. CONFIDENTIAL — For Internal, Audit, and Regulatory Examination Use Only.

Sheet Risk Register
A1: BFS INFORMATION SECURITY RISK REGISTER | CONFIDENTIAL | Aligned with BFS-ISMS-003
A3: Risk ID | B3: Risk Title | C3: Risk Category | D3: CIA Classification | E3: Risk Statement | F3: Identification Source | G3: Affected Assets | H3: Affected Interested Parties | I3: Threat Source | J3: Vulnerability | K3: Existing Controls | L3: Inherent Likelihood | M3: Inherent Impact | N3: Inherent Score | O3: Inherent Risk Level | P3: Current Likelihood | Q3: Current Impact | R3: Current Score | S3: Current Risk Level | T3: Risk Owner | U3: Risk Treatment Decision | V3: Treatment Rationale | W3: Planned / Selected Controls | X3: Target Residual Likelihood | Y3: Target Residual Impact | Z3: Target Residual Score | AA3: Target Residual Risk Level | AB3: Implementation Owner | AC3: Target Completion Date | AD3: Monitoring / Review Frequency | AE3: Effectiveness Measurement | AF3: Treatment Status | AG3: Risk Owner Approval | AH3: Last Reassessment Date | AI3: Risk Status | AJ3: Remarks
A4: BFS-RISK-2025-0001 | B4: Ransomware compromise of internet-facing infrastructure | C4: External Attack | D4: Confidentiality, Integrity, Availability | E4: A ransomware threat actor could exploit unpatched vulnerabilities in internet-facing VPN/RDP infrastructure affecting core banking systems and customer data resulting in extended service outage, customer data exfiltration, BSP material sanctions, and PHP 50-500M financial loss. | F4: Threat-Based + Threat Intelligence | G4: Core banking platform; customer data stores; VPN/RDP infrastructure; backup systems | H4: Customers; BSP; NPC; shareholders; employees | I4: External Cybercriminal (Ransomware Operators) | J4: Internet-facing infrastructure with potential unpatched CVEs; VPN architecture vs zero-trust target state; backup integrity risks | K4: BFS-ISP-007 vulnerability management; BFS-ISP-006 access control; BFS-ISP-010 endpoint protection (EDR); BFS-ISP-011 backup; immutable backups partial | L4: 4 | M4: 5 | N4: 20 | O4: CRITICAL | P4: 4 | Q4: 5 | R4: 20 | S4: CRITICAL | T4: Chief Information Officer | U4: MODIFY | V4: AVOID infeasible (cannot cease internet operations). MODIFY dominant via controls. TRANSFER (cyber insurance) for residual financial impact only. ACCEPT prohibited (CRITICAL). | W4: BFS-ISP-007 24-hour SLA for KEV/CRITICAL CVEs; BFS-ISP-006 ZTNA migration eliminating VPN; BFS-ISP-010 EDR with ransomware behavioral detection; BFS-ISP-011 immutable backups + tested recovery; cyber insurance | X4: 2 | Y4: 3 | Z4: 6 | AA4: MEDIUM | AB4: Head of IT Security / Head of Infrastructure Engineering | AC4: 2025-12-31 | AD4: Monthly (CRITICAL) | AE4: Mean Time to Patch KEV ≤24hr; ZTNA coverage ≥95%; EDR detection rate ≥99%; quarterly recovery exercise success | AF4: In Progress | AG4: CISO+CIO+CRO joint approval 2025-04-15; Board AC notified | AH4: 2025-04-15 | AI4: Active | AJ4: Top-priority risk per Board Audit & Risk Committee. Monthly status reporting until residual reaches MEDIUM. Companion controls: BFS-ISP-011-DRP.
A5: BFS-RISK-2025-0002 | B5: Business Email Compromise (BEC) targeting payment authorization | C5: External Attack | D5: Integrity, Confidentiality | E5: An external threat actor could use spoofed/compromised email to socially engineer authorized personnel into initiating fraudulent wire transfers or vendor payment redirections affecting BFS treasury and customer payment operations resulting in direct financial loss and customer trust damage. | F5: Threat-Based + Sector Threat Intelligence (FS-ISAC) | G5: Email infrastructure; treasury operations; vendor payment systems; finance team workflows | H5: BFS treasury; customers; vendors; auditors | I5: External Cybercriminal (Financial Fraud Operators) | J5: Email-based payment authorization workflows; insufficient out-of-band verification; potential SPF/DKIM/DMARC gaps | K5: BFS-ISP-013 email security gateway; SPF/DKIM/DMARC partial; BFS-ISP-014 security awareness training; manual callback verification for high-value | L5: 5 | M5: 4 | N5: 20 | O5: CRITICAL | P5: 4 | Q5: 4 | R5: 16 | S5: CRITICAL | T5: Chief Financial Officer | U5: MODIFY | V5: Email is essential business function. Controls reduce both likelihood (technical email controls) and impact (procedural verification). Cyber insurance for residual. | W5: DMARC enforcement (p=reject); BFS-ISP-013 advanced email security with impersonation detection; mandatory dual approval for transfers >PHP 1M; mandatory callback to verified number for any payment change request; quarterly BEC simulation training | X5: 3 | Y5: 3 | Z5: 9 | AA5: MEDIUM | AB5: CFO Office / Head of IT Security | AC5: 2025-09-30 | AD5: Quarterly (HIGH) | AE5: DMARC reject coverage 100%; BEC simulation click rate ≤5%; verified callback evidence in 100% of payment changes | AF5: In Progress | AG5: CISO+CFO approved 2025-04-10; Board AC notified | AH5: 2025-04-10 | AI5: Active | AJ5: Industry data shows BEC as #1 cybercrime by financial loss. Coordinate with HR on mandatory training; with vendor management for vendor verification.
A6: BFS-RISK-2025-0003 | B6: DDoS attack disrupting customer-facing banking channels | C6: External Attack | D6: Availability | E6: A DDoS threat actor could overwhelm internet-facing customer banking channels (online banking, mobile API, payment gateways) resulting in customer-facing service unavailability, customer dissatisfaction, and potential RA 11765 customer protection implications. | F6: Threat-Based + Sector Threat Intelligence | G6: Customer-facing channels; CDN; web application firewalls; DNS; payment APIs | H6: Retail customers; corporate customers; BSP; regulators | I6: External Cybercriminal (Hacktivist / Extortion / State-Sponsored) | J6: Internet-facing services exposed; potential capacity limits; DDoS protection effectiveness against L7 attacks | K6: Cloud-based DDoS protection (provider); WAF; rate limiting; CDN; BFS-ISP-013 network segmentation | L6: 4 | M6: 4 | N6: 16 | O6: CRITICAL | P6: 3 | Q6: 3 | R6: 9 | S6: MEDIUM | T6: Head of IT Operations | U6: MODIFY | V6: Customer-facing presence essential. Multi-layered DDoS protection cost-effective. Cannot AVOID. TRANSFER inappropriate. | W6: Enhanced cloud DDoS with L7 protection; geo-blocking for non-PH traffic where legitimate; rate limiting at API gateway; surge capacity provisioning; runbook for DDoS response per BFS-ISP-036 | X6: 2 | Y6: 3 | Z6: 6 | AA6: MEDIUM | AB6: Head of Network / Head of Cloud Engineering | AC6: 2025-08-31 | AD6: Quarterly | AE6: DDoS exercise: customer-facing services maintain availability under 100Gbps simulated attack; MTTR <30 min for L7 attacks | AF6: Implemented | AG6: CISO+CIO approved 2025-03-15 | AH6: 2025-04-01 | AI6: Active | AJ6: Customer-facing channels validated against simulated DDoS quarterly per BFS-ISP-036.
A7: BFS-RISK-2025-0004 | B7: Credential theft via phishing targeting BFS personnel | C7: External Attack | D7: Confidentiality, Integrity | E7: External phishing campaigns could harvest BFS personnel credentials enabling unauthorized access to BFS systems including email, SaaS applications, and remote access infrastructure resulting in lateral movement, data exfiltration, and potential ransomware staging. | F7: Threat-Based + Past Incidents | G7: Identity infrastructure; email; SaaS applications; VPN/ZTNA; user endpoints | H7: BFS personnel; customers (downstream); BSP | I7: External Cybercriminal (Credential Harvesters) | J7: Personnel susceptibility to phishing; password-only authentication on legacy systems; partial MFA coverage | K7: BFS-ISP-005 MFA on critical systems; BFS-ISP-014 security awareness training; phishing simulation; email security gateway | L7: 5 | M7: 4 | N7: 20 | O7: CRITICAL | P7: 4 | Q7: 3 | R7: 12 | S7: HIGH | T7: Chief Information Security Officer | U7: MODIFY | V7: Phishing is unavoidable threat. Defense-in-depth via training (likelihood) + MFA (impact) + monitoring (detection). | W7: 100% MFA coverage including legacy applications via federation/PAM; phishing-resistant authentication (FIDO2) for privileged users per BFS-ISP-005; monthly phishing simulation per BFS-ISP-014; conditional access policies; behavioral analytics for anomalous logins | X7: 3 | Y7: 2 | Z7: 6 | AA7: MEDIUM | AB7: Head of Identity & Access Management / CISO Office | AC7: 2025-10-31 | AD7: Quarterly (HIGH) | AE7: MFA coverage 100%; phishing simulation click rate ≤8%; credential reuse detection rate ≥95%; anomalous login detection rate ≥90% | AF7: In Progress | AG7: CISO approved 2025-04-05; Board AC notified | AH7: 2025-04-05 | AI7: Active | AJ7: Phishing-resistant FIDO2 rollout phased: privileged users Q2, all admin Q3, all users Q4.
A8: BFS-RISK-2025-0005 | B8: API abuse / scraping of customer banking APIs | C8: External Attack | D8: Confidentiality, Integrity | E8: External attackers could exploit insecure APIs (BOLA, broken authentication, excessive data exposure) in customer banking platforms to extract customer data at scale, conduct fraud, or enumerate accounts resulting in customer data exposure and potential RA 10173 NPC notification. | F8: Threat-Based + OWASP API Top 10 + Penetration Testing | G8: Customer-facing APIs; API gateway; mobile/web banking applications; customer data | H8: Customers; NPC; BSP | I8: External Cybercriminal (API Abusers / Fraudsters) | J8: API security gaps; insufficient rate limiting per user; potential authorization flaws; excessive data exposure in responses | K8: BFS-ISP-016 API security review; API gateway with auth; rate limiting; BFS-ISP-018 penetration testing | L8: 4 | M8: 4 | N8: 16 | O8: CRITICAL | P8: 3 | Q8: 3 | R8: 9 | S8: MEDIUM | T8: Head of Software Engineering | U8: MODIFY | V8: APIs essential for customer experience. Defense via secure design + testing + runtime protection. | W8: API security scanning in CI/CD per BFS-ISP-016; API runtime protection (anomaly detection); per-user rate limiting; OAuth 2.0 / OIDC enforcement; comprehensive penetration testing per BFS-ISP-018 quarterly | X8: 2 | Y8: 3 | Z8: 6 | AA8: MEDIUM | AB8: Head of Application Security | AC8: 2025-11-30 | AD8: Quarterly | AE8: OWASP API Top 10 coverage 100%; pen test findings remediated per SLA; API anomaly detection rate ≥85% | AF8: In Progress | AG8: CISO+HSE approved 2025-04-08 | AH8: 2025-04-08 | AI8: Active | AJ8: Open Banking direction may expand API surface — re-evaluate annually.
A9: BFS-RISK-2025-0006 | B9: Supply chain compromise of third-party software dependency | C9: External Attack | D9: Confidentiality, Integrity, Availability | E9: A nation-state or sophisticated threat actor could compromise a software supply chain component (npm package, library, vendor update) used in BFS applications resulting in malicious code execution within BFS production systems and potential lateral movement. | F9: Threat-Based + Industry Incidents (SolarWinds, log4j, xz-utils) | G9: All applications using third-party dependencies; CI/CD pipelines; production systems | H9: BFS personnel; customers; BSP | I9: Nation-State APT / Sophisticated Cybercriminal | J9: Third-party dependency consumption without comprehensive verification; CI/CD pipeline trust | K9: BFS-ISP-016 SBOM generation partial; dependency scanning (SCA); BFS-ISP-016 §6.3 pipeline security | L9: 3 | M9: 5 | N9: 15 | O9: CRITICAL | P9: 3 | Q9: 4 | R9: 12 | S9: HIGH | T9: Head of Software Engineering | U9: MODIFY | V9: Cannot avoid third-party dependencies. Defense via SBOM, scanning, runtime protection, vendor security review. | W9: Comprehensive SBOM per BFS-ISP-016 §7; SCA in CI/CD with vulnerability blocking; dependency pinning + update review process; runtime application protection; vendor security assessment per BFS-ISP-031 | X9: 2 | Y9: 4 | Z9: 8 | AA9: MEDIUM | AB9: Head of Application Security / Head of DevSecOps | AC9: 2026-03-31 | AD9: Quarterly (HIGH) | AE9: SBOM coverage 100%; SCA vulnerability detection in <24hr; mean time to remediate critical SCA findings ≤7 days | AF9: In Progress | AG9: CISO+HSE approved 2025-04-12; Board AC notified | AH9: 2025-04-12 | AI9: Active | AJ9: Difficult to fully mitigate. Investment continues across SBOM, SCA, runtime protection, vendor governance.
A10: BFS-RISK-2025-0007 | B10: Card-skimming / Magecart-style attacks on payment pages | C10: External Attack | D10: Confidentiality, Integrity | E10: External attackers could inject malicious JavaScript into customer-facing payment pages (via compromised third-party scripts or own application) to steal cardholder data resulting in PCI DSS non-compliance, customer financial loss, and BSP/PCI council scrutiny. | F10: Threat-Based + PCI DSS v4.0 §6.4.3 | G10: Customer-facing web payment interfaces; CDE-adjacent web infrastructure; third-party scripts | H10: Cardholders; PCI Security Standards Council; card networks; BSP | I10: External Cybercriminal (Magecart-style operators) | J10: Third-party scripts on payment pages; lack of subresource integrity; client-side script monitoring gaps | K10: PCI DSS controls; CSP partial; BFS-ISP-016 application security review | L10: 3 | M10: 4 | N10: 12 | O10: HIGH | P10: 3 | Q10: 3 | R10: 9 | S10: MEDIUM | T10: Chief Information Security Officer | U10: MODIFY | V10: PCI DSS v4.0 §6.4.3 mandates script monitoring on payment pages. MODIFY essential for compliance. | W10: Per PCI DSS §6.4.3 - inventory all scripts on payment pages; integrity verification; client-side script monitoring; iframe isolation of payment forms; subresource integrity | X10: 2 | Y10: 3 | Z10: 6 | AA10: MEDIUM | AB10: Head of Application Security | AC10: 2025-12-31 | AD10: Quarterly | AE10: Script inventory complete; SRI deployed; runtime monitoring detects unauthorized script changes within 5 minutes | AF10: In Progress | AG10: CISO approved 2025-04-15 | AH10: 2025-04-15 | AI10: Active | AJ10: PCI DSS v4.0 future-dated requirement effective 2025-03-31. Compliance gap closure underway.
A11: BFS-RISK-2025-0008 | B11: Mobile banking application reverse engineering / modification | C11: External Attack | D11: Confidentiality, Integrity | E11: Attackers could reverse engineer or modify the BFS mobile banking application to bypass security controls, extract embedded secrets, or distribute malicious modified versions resulting in customer fraud, credential theft, and reputational damage. | F11: Threat-Based + Mobile Threat Intelligence | G11: BFS mobile banking applications (iOS/Android); embedded secrets; customer authentication flows | H11: Mobile banking customers; BFS; app stores | I11: External Cybercriminal (Mobile Malware Operators / Fraudsters) | J11: Mobile applications inherently exposed to client-side analysis; potential embedded secrets; runtime manipulation possible | K11: BFS-ISP-022 mobile security; certificate pinning; basic obfuscation; runtime root/jailbreak detection | L11: 4 | M11: 3 | N11: 12 | O11: HIGH | P11: 3 | Q11: 3 | R11: 9 | S11: MEDIUM | T11: Head of Mobile Engineering | U11: MODIFY | V11: Mobile presence essential. Defense via obfuscation, RASP, server-side verification of all critical operations. | W11: Advanced code obfuscation; runtime application self-protection (RASP); strong certificate pinning; no embedded secrets policy; server-side verification of all critical client claims; app integrity verification at backend | X11: 2 | Y11: 3 | Z11: 6 | AA11: MEDIUM | AB11: Head of Mobile Engineering / Head of Application Security | AC11: 2025-10-31 | AD11: Semi-annually | AE11: Independent mobile security assessment shows no critical findings; RASP detection rate ≥90%; certificate pinning coverage 100% | AF11: In Progress | AG11: CISO+HSE approved 2025-04-12 | AH11: 2025-04-12 | AI11: Active | AJ11: Coordinate with mobile development team for SDK selection. Annual mobile penetration testing per BFS-ISP-018.
A12: BFS-RISK-2025-0009 | B12: Malicious insider data exfiltration of customer information | C12: Insider Threat | D12: Confidentiality | E12: A malicious BFS insider with authorized access to customer data could exfiltrate customer records for personal gain, sale to third parties, or use in fraud resulting in mass customer data breach, RA 10173 NPC notification, and material reputational damage. | F12: Threat-Based + Industry Incidents | G12: Customer databases; CRM; data warehouse; export tools; personnel with data access | H12: Customers; NPC; BSP; affected employees (subject to disciplinary action) | I12: Malicious Insider (Disgruntled Employee / Financially Motivated) | J12: Personnel with broad data access; insufficient data movement monitoring; potential excess privileges per BFS-ISP-005 reviews | K12: BFS-ISP-005 access management; least privilege partial; BFS-ISP-021 background checks; BFS-ISP-008 audit logging | L12: 4 | M12: 5 | N12: 20 | O12: CRITICAL | P12: 3 | Q12: 4 | R12: 12 | S12: HIGH | T12: Chief Information Security Officer | U12: MODIFY | V12: Insider risk inherent to operations. Defense via prevention (least privilege, segregation), detection (DLP, UEBA), response (incident handling). | W12: Enterprise DLP deployment per BFS-ISP-013; UEBA for anomalous data access patterns; quarterly access reviews per BFS-ISP-005 §8; segregation of duties enforcement per BFS-ISP-025; mandatory background checks renewal per BFS-ISP-021 | X12: 2 | Y12: 4 | Z12: 8 | AA12: MEDIUM | AB12: CISO Office / Head of HR | AC12: 2025-12-31 | AD12: Quarterly (HIGH) | AE12: DLP coverage 100% on customer data; UEBA detection rate ≥80%; access review completion ≥98%; SoD violations resolved within 30 days | AF12: In Progress | AG12: CISO+CHRO approved 2025-04-15; Board AC notified | AH12: 2025-04-15 | AI12: Active | AJ12: Cultural and procedural controls equally important to technical. Coordinate with HR ethics, internal audit, compliance hotline.
A13: BFS-RISK-2025-0010 | B13: Privileged user abuse / unauthorized administrative actions | C13: Insider Threat | D13: Confidentiality, Integrity, Availability | E13: A privileged user (system administrator, DBA, application owner) could abuse elevated privileges to access unauthorized data, make unauthorized configuration changes, or facilitate fraud resulting in confidentiality/integrity compromise and potential systematic control failure. | F13: Threat-Based + Audit Findings | G13: Production systems; databases; cloud admin consoles; PAM systems; audit logs | H13: All BFS stakeholders; auditors; BSP | I13: Malicious Insider (Privileged User) | J13: Necessarily-elevated privileges; potential PAM coverage gaps; audit log integrity dependencies | K13: BFS-ISP-005 §7 privileged access management; PAM deployed for critical systems; BFS-ISP-008 audit logging with integrity protection; quarterly privileged access reviews | L13: 3 | M13: 5 | N13: 15 | O13: CRITICAL | P13: 2 | Q13: 4 | R13: 8 | S13: MEDIUM | T13: Chief Information Officer | U13: MODIFY | V13: Privileged access necessary. Comprehensive PAM + monitoring + segregation = defense in depth. | W13: 100% PAM coverage including cloud and SaaS; just-in-time elevation; session recording for all privileged sessions; UEBA on privileged accounts; quarterly access certification per BFS-ISP-005 §8.2; SoD enforcement | X13: 2 | Y13: 3 | Z13: 6 | AA13: MEDIUM | AB13: Head of Identity & Access Management | AC13: 2025-09-30 | AD13: Quarterly (HIGH) | AE13: PAM coverage 100%; JIT activation success ≥99%; session recording retention 1 year; access certification completion 100% | AF13: In Progress | AG13: CISO+CIO approved 2025-04-10; Board AC notified | AH13: 2025-04-10 | AI13: Active | AJ13: PAM expansion to cover all cloud platforms and SaaS admin in phases through Q3.
A14: BFS-RISK-2025-0011 | B14: Negligent insider - unintended data exposure via misconfiguration | C14: Insider Threat | D14: Confidentiality | E14: A BFS employee could unintentionally expose customer or business data through misconfigured cloud storage, public document sharing, email error, or unsecured collaboration tool resulting in data exposure, RA 10173 implications, and required NPC notification. | F14: Threat-Based + Industry Incidents | G14: Cloud storage (S3, OneDrive, SharePoint); collaboration tools; email; databases | H14: Customers; NPC; BSP; affected employees | I14: Negligent Insider | J14: Configuration complexity; insufficient training on secure data handling; default-public configurations | K14: BFS-ISP-014 awareness training; BFS-ISP-033 cloud security baseline; BFS-ISP-013 email DLP; configuration scanning partial | L14: 4 | M14: 4 | N14: 16 | O14: CRITICAL | P14: 3 | Q14: 3 | R14: 9 | S14: MEDIUM | T14: Data Protection Officer | U14: MODIFY | V14: Human error inevitable. Combined technical (default-secure config, automated scanning) and procedural (training, classification) controls. | W14: Cloud security posture management (CSPM) with auto-remediation; mandatory data classification per BFS-ISP-003; quarterly handling training per BFS-ISP-014; DLP across email/cloud/endpoint; default-private collaboration settings | X14: 2 | Y14: 3 | Z14: 6 | AA14: MEDIUM | AB14: DPO / Head of Cloud Security | AC14: 2025-08-31 | AD14: Quarterly | AE14: CSPM coverage 100%; auto-remediation rate ≥80% for known misconfigurations; DLP block rate for sensitive data sent externally ≥95% | AF14: In Progress | AG14: CISO+DPO approved 2025-04-08 | AH14: 2025-04-08 | AI14: Active | AJ14: Most data breaches sector-wide attributable to negligence rather than malice. Training emphasis.
A15: BFS-RISK-2025-0012 | B15: Departing employee data theft prior to or during offboarding | C15: Insider Threat | D15: Confidentiality | E15: An employee in notice period or recently terminated could exfiltrate customer data, intellectual property, or sensitive documents prior to access revocation resulting in data exposure, IP loss, and potential competitive harm. | F15: Threat-Based + Industry Incidents | G15: Customer data; intellectual property; design documents; business plans; source code | H15: BFS; customers (downstream); future employer (if competitor) | I15: Departing Insider | J15: Notice period access maintenance; offboarding gaps; personal device use | K15: BFS-ISP-021 §6 offboarding procedures; BFS-ISP-005 deprovisioning; exit interviews | L15: 3 | M15: 3 | N15: 9 | O15: MEDIUM | P15: 2 | Q15: 3 | R15: 6 | S15: MEDIUM | T15: Chief Human Resources Officer | U15: MODIFY | V15: Employee departures inevitable. Enhanced monitoring during notice period + same-day deprovisioning + UEBA detection. | W15: Enhanced UEBA monitoring during notice period; same-day access revocation per BFS-ISP-021 §6; DLP enhanced sensitivity for departing employees; mandatory device return; legal review of departure agreements; alumni access termination within 24 hours | X15: 2 | Y15: 2 | Z15: 4 | AA15: LOW | AB15: CHRO / Head of IAM | AC15: 2025-07-31 | AD15: Semi-annually | AE15: 100% same-day deprovisioning; UEBA detection of departing employee anomalies ≥85%; departing employee data exfiltration incidents ≤2/year | AF15: Implemented | AG15: CISO+CHRO approved 2025-03-20 | AH15: 2025-03-20 | AI15: Active | AJ15: Coordinate with managers on notice period activity awareness.
... A48: BFS-RISK-2025-0045 | B48: Cyber-physical incident at critical Philippine infrastructure (power, telecoms) | C48: Business Continuity Risk | D48: Availability | E48: Cyber-physical incident at critical Philippine infrastructure (power grid, telecommunications) could affect BFS operations through dependency on these services resulting in operational disruption beyond BFS direct control. | F48: Threat-Based + Critical Infrastructure Analysis | G48: BFS operations dependent on power and telecommunications; communication channels; data center power | H48: BFS; affected industries; entire Philippine economy | I48: Critical Infrastructure (Power / Telecommunications) | J48: External infrastructure dependency; alternative provider limitations | K48: Backup power (UPS, generator); multiple telecommunications providers; cloud infrastructure providing geographic distribution | L48: 2 | M48: 4 | N48: 8 | O48: MEDIUM | P48: 2 | Q48: 3 | R48: 6 | S48: MEDIUM | T48: Chief Operating Officer | U48: MODIFY | V48: External infrastructure beyond BFS control. Defense via redundancy, BCP, alternative paths. | W48: Backup power validated; multiple telecommunications providers; cloud-based operations with geographic distribution; BCP scenarios for infrastructure failure; satellite backup considered for tier-1 | X48: 1 | Y48: 3 | Z48: 3 | AA48: LOW | AB48: Head of Infrastructure / Head of Network | AC48: 2025-12-31 | AD48: Semi-annually | AE48: Backup power tested monthly; telecommunications redundancy validated; BCP scenario exercises | AF48: Implemented | AG48: COO+CIO approved 2025-03-28 | AH48: 2025-03-28 | AI48: Active | AJ48: PH infrastructure vulnerability inherent. Defense in depth approach.

Sheet Risk Matrix
A1: BFS RISK MATRIX (5×5) — Likelihood × Impact
A2: Per BFS-ISMS-003 Section 5
A4: L I K E L I H O O D | B4: 5 - Almost Certain | C4: 5 | D4: 10 | E4: 15 | F4: 20 | G4: 25
B5: 4 - Likely | C5: 4 | D5: 8 | E5: 12 | F5: 16 | G5: 20
B6: 3 - Possible | C6: 3 | D6: 6 | E6: 9 | F6: 12 | G6: 15
B7: 2 - Unlikely | C7: 2 | D7: 4 | E7: 6 | F7: 8 | G7: 10
B8: 1 - Rare | C8: 1 | D8: 2 | E8: 3 | F8: 4 | G8: 5
C9: 1 Negligible | D9: 2 Minor | E9: 3 Moderate | F9: 4 Major | G9: 5 Catastrophic
C10: I M P A C T
B13: LEGEND
B14: CRITICAL (15-25) | C14: UNACCEPTABLE — Immediate treatment required; reduce to HIGH within 90 days; CISO+CIO+CRO+CEO approval
B15: HIGH (10-14) | C15: TOLERABLE WITH CONDITIONS — Treatment plan required; quarterly review; CISO+executive risk owner approval
B16: MEDIUM (5-9) | C16: ACCEPTABLE WITH CONTROLS — Documented in Risk Register; annual review; risk owner approval
B17: LOW (1-4) | C17: ACCEPTABLE — Routine business operations; annual review; risk owner sign-off

Sheet Dashboard
A1: RISK REGISTER DASHBOARD
A3: Risks by Current Risk Level | F3: Risks by Category
A4: Risk Level | B4: Count | C4: % of Total | D4: Color | F4: Category | G4: Count | H4: % of Total
A5: CRITICAL | B5: =COUNTIF('Risk Register'!S:S,"CRITICAL") -> 2 | C5: =B5/SUM($B$5:$B$8) -> 0.044444444 | D5: ███ | F5: External Attack | G5: =COUNTIF('Risk Register'!C:C,"External Attack") -> 8 | H5: =G5/SUM($G$5:$G$14) -> 0.098765432
A6: HIGH | B6: =COUNTIF('Risk Register'!S:S,"HIGH") -> 5 | C6: =B6/SUM($B$5:$B$8) -> 0.11111111 | D6: ███ | F6: Insider Threat | G6: =COUNTIF('Risk Register'!C:C,"Insider Threat") -> 5 | H6: =G6/SUM($G$5:$G$14) -> 0.061728395
A7: MEDIUM | B7: =COUNTIF('Risk Register'!S:S,"MEDIUM") -> 35 | C7: =B7/SUM($B$5:$B$8) -> 0.77777778 | D7: ███ | F7: Third-Party Risk | G7: =COUNTIF('Risk Register'!C:C,"Third-Party Risk") -> 5 | H7: =G7/SUM($G$5:$G$14) -> 0.061728395
A8: LOW | B8: =COUNTIF('Risk Register'!S:S,"LOW") -> 3 | C8: =B8/SUM($B$5:$B$8) -> 0.066666667 | D8: ███ | F8: Compliance Risk | G8: =COUNTIF('Risk Register'!C:C,"Compliance Risk") -> 5 | H8: =G8/SUM($G$5:$G$14) -> 0.061728395
A9: TOTAL | B9: =SUM(B5:B8) -> 45 | C9: 100.0% | F9: Operational Risk | G9: =COUNTIF('Risk Register'!C:C,"Operational Risk") -> 5 | H9: =G9/SUM($G$5:$G$14) -> 0.061728395
F10: Emerging / AI Risk | G10: =COUNTIF('Risk Register'!C:C,"Emerging / AI Risk") -> 6 | H10: =G10/SUM($G$5:$G$14) -> 0.074074074
F11: Physical Risk | G11: =COUNTIF('Risk Register'!C:C,"Physical Risk") -> 3 | H11: =G11/SUM($G$5:$G$14) -> 0.037037037
A12: Risks by Treatment Status | F12: Risks by Treatment Decision
A13: Status | B13: Count | C13: % of Total | F13: Treatment | G13: Count | H13: % of Total
A14: Planned | B14: =COUNTIF('Risk Register'!AF:AF,"Planned") -> 3 | C14: =B14/SUM($B$14:$B$17) -> 0.066666667 | F14: MODIFY | G14: =COUNTIF('Risk Register'!U:U,"MODIFY") -> 44 | H14: =G14/SUM($G$14:$G$18) -> 0.97777778
A15: In Progress | B15: =COUNTIF('Risk Register'!AF:AF,"In Progress") -> 31 | C15: =B15/SUM($B$14:$B$17) -> 0.68888889 | F15: MODIFY + TRANSFER | G15: =COUNTIF('Risk Register'!U:U,"MODIFY + TRANSFER") -> 1 | H15: =G15/SUM($G$14:$G$18) -> 0.022222222
A16: Implemented | B16: =COUNTIF('Risk Register'!AF:AF,"Implemented") -> 11 | C16: =B16/SUM($B$14:$B$17) -> 0.24444444 | F16: AVOID | G16: =COUNTIF('Risk Register'!U:U,"AVOID") -> 0 | H16: =G16/SUM($G$14:$G$18) -> 0
A17: Validated | B17: =COUNTIF('Risk Register'!AF:AF,"Validated") -> 0 | C17: =B17/SUM($B$14:$B$17) -> 0 | F17: TRANSFER | G17: =COUNTIF('Risk Register'!U:U,"TRANSFER") -> 0 | H17: =G17/SUM($G$14:$G$18) -> 0
F18: ACCEPT | G18: =COUNTIF('Risk Register'!U:U,"ACCEPT") -> 0 | H18: =G18/SUM($G$14:$G$18) -> 0
A22: Risk Reduction Summary (Inherent → Current → Target)
A23: Risk Stage | B23: CRITICAL | C23: HIGH | D23: MEDIUM | E23: LOW | F23: Total
A24: Inherent Risk | B24: =COUNTIF('Risk Register'!O:O,"CRITICAL") -> 15 | C24: =COUNTIF('Risk Register'!O:O,"HIGH") -> 17 | D24: =COUNTIF('Risk Register'!O:O,"MEDIUM") -> 13 | E24: =COUNTIF('Risk Register'!O:O,"LOW") -> 0 | F24: =SUM(B24:E24) -> 45
A25: Current Risk (with controls) | B25: =COUNTIF('Risk Register'!S:S,"CRITICAL") -> 2 | C25: =COUNTIF('Risk Register'!S:S,"HIGH") -> 5 | D25: =COUNTIF('Risk Register'!S:S,"MEDIUM") -> 35 | E25: =COUNTIF('Risk Register'!S:S,"LOW") -> 3 | F25: =SUM(B25:E25) -> 45
A26: Target Residual Risk | B26: =COUNTIF('Risk Register'!AA:AA,"CRITICAL") -> 0 | C26: =COUNTIF('Risk Register'!AA:AA,"HIGH") -> 0 | D26: =COUNTIF('Risk Register'!AA:AA,"MEDIUM") -> 23 | E26: =COUNTIF('Risk Register'!AA:AA,"LOW") -> 22 | F26: =SUM(B26:E26) -> 45

Sheet Reference & Schema
A1: RISK REGISTER SCHEMA & REFERENCE
A3: Risk Register Schema (BFS-ISMS-003 §8.1)
A4: Field | B4: Source | C4: Description / Validation
A5: Risk ID | B5: BFS-ISMS-003 §8.1 | C5: Unique identifier (e.g., BFS-RISK-2025-0001). Persistent across reassessments.
A6: Risk Title | B6: BFS-ISMS-003 §8.1 | C6: Short descriptive title. Maximum 120 characters.
A7: Risk Category | B7: BFS-ISMS-003 §8.1 | C7: Category for grouping: External Attack / Insider Threat / Third-Party Risk / Compliance Risk / Operational Risk / Emerging-AI Risk / Physical Risk / Data Privacy / Cloud / BCM.
A8: CIA Classification | B8: Schema Extension | C8: Confidentiality / Integrity / Availability impact dimensions. Multiple values where applicable.
A9: Risk Statement | B9: BFS-ISMS-003 §4.4 | C9: Structured statement: [THREAT] could exploit [VULNERABILITY] affecting [ASSET] resulting in [CONSEQUENCE].
A10: Identification Source | B10: BFS-ISMS-003 §8.1 | C10: How identified: Asset-Based / Threat-Based / Scenario-Based / Compliance-Based / Incident-Driven / Audit / Pen Test / Threat Intel.
A11: Affected Assets | B11: BFS-ISMS-003 §8.1 | C11: Specific BFS assets affected per BFS-ISP-001/002/015/016.
A12: Affected Interested Parties | B12: BFS-ISMS-003 §8.1 | C12: Per BFS-ISMS-002 Interested Parties Register.
A13: Threat Source | B13: BFS-ISMS-003 §8.1 | C13: External Cybercriminal / Nation-State APT / Insider / Vendor / Natural Cause / System Failure / Regulatory / AI System.
A14: Vulnerability | B14: BFS-ISMS-003 §8.1 | C14: Specific vulnerability or condition enabling the threat.
A15: Existing Controls | B15: BFS-ISMS-003 §8.1 | C15: Current controls (referenced to BFS-ISP policies and ISO 27001 Annex A).
... A31: Remarks | B31: Schema Extension | C31: Additional context, notes, dependencies, references.
A35: Likelihood Scale (BFS-ISMS-003 §5.1)
A36: Score | B36: Level | C36: Description
A37: 5 | B37: Almost Certain | C37: Expected to occur in most circumstances; threat actively targeting; weakness widely exploited; high confidence in occurrence within 12 months
A38: 4 | B38: Likely | C38: Will probably occur in most circumstances; threat capability and intent confirmed; significant weakness present
A39: 3 | B39: Possible | C39: Might occur at some time; threat capability exists; some weakness or partial controls
A40: 2 | B40: Unlikely | C40: Could occur at some time but not expected; threat capability limited or strong controls in place
A41: 1 | B41: Rare | C41: May occur only in exceptional circumstances; threat capability minimal or controls excellent
A43: Impact Scale (BFS-ISMS-003 §5.2)
A44: Score | B44: Level | C44: Description
A45: 5 | B45: Catastrophic | C45: Severe customer trust damage; PHP >500M financial loss; BSP material sanctions / loss of license risk; sustained core operational disruption; existential threat to BFS
A46: 4 | B46: Major | C46: Significant customer trust damage; PHP 50-500M financial loss; BSP supervisory action; multi-day core operational disruption; material strategic impact
A47: 3 | B47: Moderate | C47: Localized customer impact; PHP 5-50M financial loss; regulatory examination findings; hours-to-day operational impact; recoverable strategic impact
A48: 2 | B48: Minor | C48: Limited customer impact; PHP <5M financial loss; minor regulatory observations; brief operational impact; minimal strategic impact
A49: 1 | B49: Negligible | C49: No material customer impact; immaterial financial loss; no regulatory implications; minimal operational impact; no strategic impact
A51: Risk Acceptance Criteria (BFS-ISMS-003 §6.2)
A52: Risk Level | B52: Acceptance Status | C52: Specific Criteria and Conditions
A53: CRITICAL | B53: UNACCEPTABLE | C53: No CRITICAL risk shall be retained without active treatment. CRITICAL risks shall be reduced to HIGH or below within 90 days. CISO+CIO+CRO+CEO approval required for temporary residual.
A54: HIGH | B54: TOLERABLE WITH CONDITIONS | C54: Treatment plan documented with specific controls and timelines; compensating controls reduce material exposure; CISO + named executive risk owner approval; quarterly review until reduced.
A55: MEDIUM | B55: ACCEPTABLE WITH CONTROLS | C55: Appropriate controls in place per BFS-ISP series and ISO 27001 Annex A; residual documented in Risk Register; risk owner approval; semi-annual review.
A56: LOW | B56: ACCEPTABLE | C56: Acceptable as part of routine business operations. Documentation in Risk Register and annual review sufficient. Risk owner sign-off.
A58: Risk Treatment Options (BFS-ISMS-003 §7.1)
A59: Option | B59: Description | C59: When Selected
A60: MODIFY (Reduce) | B60: Apply controls to reduce likelihood, impact, or both — bringing residual risk to acceptable level | C60: Default option for most risks where suitable controls exist; cost-effective; aligned with ISO 27001 Annex A control framework
A61: AVOID | B61: Eliminate the source of risk by ceasing the activity, removing the asset, or restructuring to remove exposure | C61: Where the activity creating the risk is not essential to BFS purpose; where treatment cost exceeds business value; regulatory or ethical concerns
A62: TRANSFER | B62: Share or transfer the risk to another party — typically through insurance, contractual transfer, or outsourcing | C62: Where another party is better positioned to manage; where insurance is cost-effective; where regulatory framework supports transfer
...
