Workbook

Sheet Cover
A1: BFS INFORMATION SECURITY MANAGEMENT SYSTEM
A5: STATEMENT OF APPLICABILITY WORKING REGISTER
A11: Operational Companion to BFS-ISMS-004 Statement of Applicability ISO/IEC 27001:2022 Annex A — All 93 Controls Clause 6.1.3(d) Documented Information
B17: Reference | D17: BFS-ISMS-004-WR (Working Register)
B18: Authoritative Document | D18: BFS-ISMS-004 Statement of Applicability (.docx)
B19: Relationship to Authoritative | D19: Operational tracking artifact derived from BFS-ISMS-004. The .docx is the source of truth for applicability decisions and justifications. This Working Register adds operational columns for evidence tracking, effectiveness measurement, and cross-mapping.
B20: Version | D20: 1.0
B21: Classification | D21: CONFIDENTIAL — Authorized Internal and Audit Use Only
B22: Effective Date | D22: 46113
B23: Annual Review | D23: April 2026 + material triggers
B24: Framework | D24: ISO/IEC 27001:2022 Annex A (93 controls); ISO/IEC 27002:2022 (control attributes)
B25: Operational Updates | D25: Continuous (evidence dates, verifications, effectiveness)
B26: Annual Updates | D26: Consolidated into next BFS-ISMS-004 .docx version
B27: Material Updates | D27: Applicability changes require formal approval before propagating to BFS-ISMS-004
B28: Owner | D28: Chief Information Security Officer
B29: Maintainer | D29: CISO Office / Risk Management Team
B30: Total Controls | D30: 93 (A.5: 37 / A.6: 8 / A.7: 14 / A.8: 34)
B31: Applicable Controls | D31: 93
B32: Not Applicable Controls | D32: 0
B33: Approval | D33: CISO + CIO + CRO + Board Audit & Risk Committee
A37: © BFS Financial Services. CONFIDENTIAL — For Internal, Audit, and Regulatory Examination Use Only.

Sheet SoA Register
A1: BFS-ISMS-004 STATEMENT OF APPLICABILITY — OPERATIONAL WORKING REGISTER | CONFIDENTIAL | All 93 ISO 27001:2022 Annex A Controls
A3: Ctrl ID | B3: Control Title | C3: Applicable? | D3: Justification & BFS Implementation Context | E3: Primary Implementation Reference | F3: Control Theme | G3: Control Type | H3: Information Security Properties (CIA) | I3: Cybersecurity Concept (NIST CSF) | J3: Operational Capability | K3: Security Domain | L3: Implementation Status | M3: Maturity Level (1-5) | N3: Implementation Date | O3: Target Date (Planned/Partial) | P3: Control Owner (Named) | Q3: Control Operator (Function) | R3: Approver (Last Approval) | S3: Primary Evidence Type | T3: Evidence Location | U3: Last Verification Date | V3: Verification Method | W3: Verifier | X3: Last Audit Date | Y3: Open Audit Findings | Z3: Risks Mitigated (Risk IDs) | AA3: Control Effectiveness | AB3: Compensating Controls | AC3: BSP Circular Reference | AD3: PCI DSS v4.0 Reference | AE3: RA 10173 Reference | AF3: NIST CSF 2.0 Reference | AG3: Other Standards | AH3: Last Reviewed Date | AI3: Next Review Date | AJ3: Review Cycle | AK3: Change History | AL3: Implementation Notes | AM3: Auditor Notes | AN3: Remarks
A4: A.5.1 | B4: Policies for information security | C4: Applicable | D4: Foundational requirement for any ISMS. BFS maintains a comprehensive policy hierarchy: TIER 1 Top-Level Policy (BFS-ISMS-001), TIER 2 ISMS framework documents (BFS-ISMS-002 through BFS-ISMS-010), TIER 2 technical control policies (BFS-ISP-001 through BFS-ISP-029). Policies are reviewed annually and approved at appropriate authority levels. | E4: BFS-ISMS-001 (Top-Level Policy) + entire BFS-ISP series | F4: A.5 Organizational | G4: Preventive | H4: Confidentiality, Integrity, Availability | I4: IDENTIFY, PROTECT | J4: Governance | K4: Governance and Ecosystem, Resilience | L4: Implemented | M4: 3 | P4: CISO | R4: CISO + CIO (per Mgmt Review) | Z4: BFS-RISK-2026-0022 | AA4: TBD | AC4: Circular 1140 §III | AD4: Req 12.1 | AF4: GV.PO-01,02 | AH4: 46113 | AI4: 46478 | AJ4: Annual | AK4: v1.0 Apr-2026 — Initial SoA
A5: A.5.2 | B5: Information security roles and responsibilities | C5: Applicable | D5: Roles and responsibilities defined at three governance tiers (Strategic/Executive/Operational) per BFS-ISMS-001 Section 5. Each subordinate BFS-ISP policy defines control-specific roles. Independent reporting lines preserved for CISO, DPO, and Internal Audit. | E5: BFS-ISMS-001 §5; all BFS-ISP roles sections | F5: A.5 Organizational | G5: Preventive | H5: Confidentiality, Integrity, Availability | I5: IDENTIFY | J5: Governance | K5: Governance and Ecosystem | L5: Implemented | M5: 3 | P5: CISO | R5: CISO + CIO (per Mgmt Review) | AA5: TBD | AC5: Circular 1140 §III; Circular 1048 §3.1 | AD5: Req 12.4 | AF5: GV.RR-01,02,03 | AH5: 46113 | AI5: 46478 | AJ5: Annual | AK5: v1.0 Apr-2026 — Initial SoA
A6: A.5.3 | B6: Segregation of duties | C6: Applicable | D6: Critical control for a financial institution to prevent fraud, error, and unauthorized actions. SoD requirements apply to financial transactions, IT operations, security operations, and access governance. Privileged access governance per BFS-ISP-005 enforces SoD principles. | E6: BFS-ISP-025 (forthcoming); BFS-ISP-005; BFS-ISP-006 | F6: A.5 Organizational | G6: Preventive | H6: Confidentiality, Integrity, Availability | I6: PROTECT | J6: Governance | K6: Governance and Ecosystem | L6: Partially Implemented | M6: 2 | O6: 2026-Q4 / 2027-Q1 | P6: CISO + CRO | R6: CISO + CIO (per Mgmt Review) | AB6: See Implementation Notes | AD6: Req 6.4.4 | AF6: GV.RR-02; PR.AA-05 | AH6: 46113 | AI6: 46478 | AJ6: Annual | AK6: v1.0 Apr-2026 — Initial SoA
A7: A.5.4 | B7: Management responsibilities | C7: Applicable | D7: Management at all levels is accountable for compliance with BFS information security policies within their span of control. Reflected in BFS-ISMS-001 governance structure, executive accountability matrix, and business unit head responsibilities defined throughout the BFS-ISP series. | E7: BFS-ISMS-001 §5 and §7 | F7: A.5 Organizational | G7: Preventive | H7: Confidentiality, Integrity, Availability | I7: IDENTIFY | J7: Governance | K7: Governance and Ecosystem | L7: Implemented | M7: 3 | P7: CISO + CHRO | R7: CISO + CIO (per Mgmt Review) | AA7: TBD | AC7: Circular 1140 §III | AF7: GV.OC-02,03 | AH7: 46113 | AI7: 46478 | AJ7: Annual | AK7: v1.0 Apr-2026 — Initial SoA
A8: A.5.5 | B8: Contact with authorities | C8: Applicable | D8: BFS maintains documented contact with BSP, NPC, SEC, AMLC, NBI Cybercrime Division, and PNP-ACG. Specific notification timelines and procedures are operationalized in BFS-ISP-017 (Incident Response) — BSP within 2 hours for cybersecurity incidents, NPC within 72 hours for personal data breaches. | E8: BFS-ISP-017 §5.9; CCO + Legal coordination | F8: A.5 Organizational | G8: Preventive | H8: Confidentiality, Integrity, Availability | I8: IDENTIFY, PROTECT | J8: Governance | K8: Governance and Ecosystem | L8: Implemented | M8: 3 | P8: CISO + CRO + DPO + CCO | R8: CISO + CIO (per Mgmt Review) | AA8: TBD | AC8: Circular 1140 §IV | AE8: RA 10173 §16 | AF8: GV.SC-01,02 | AH8: 46113 | AI8: 46478 | AJ8: Annual | AK8: v1.0 Apr-2026 — Initial SoA
A9: A.5.6 | B9: Contact with special interest groups | C9: Applicable | D9: BFS participates in sector information sharing through BSP-ISAC and FS-ISAC channels. Industry threat intelligence and lessons learned shape ISMS evolution. Membership in security professional bodies maintained for CISO Office personnel. | E9: BFS-ISP-013 (threat intel); CISO Office | F9: A.5 Organizational | G9: Preventive | H9: Confidentiality, Integrity, Availability | I9: PROTECT, DETECT, RESPOND | J9: Governance | K9: Defence | L9: Implemented | M9: 3 | P9: CISO + CCO | R9: CISO + CIO (per Mgmt Review) | Z9: BFS-RISK-2026-0001,0002,0006 | AA9: TBD | AC9: Circular 1140 §V; FS-ISAC | AF9: GV.SC; ID.RA-02,03 | AH9: 46113 | AI9: 46478 | AJ9: Annual | AK9: v1.0 Apr-2026 — Initial SoA
A10: A.5.7 | B10: Threat intelligence | C10: Applicable | D10: Active threat intelligence program collecting, analyzing, and disseminating threat information from open-source feeds, commercial subscriptions, sector ISACs, BSP/NPC advisories, and MITRE ATT&CK Framework. Threat intelligence drives detection rule development and Purple Team exercise priorities. | E10: BFS-ISP-013 §5.4; BFS-ISP-018 (Purple Team) | F10: A.5 Organizational | G10: Preventive / Detective | H10: Confidentiality, Integrity, Availability | I10: IDENTIFY, DETECT, RESPOND | J10: Threat and vulnerability management | K10: Defence, Resilience | L10: Implemented | M10: 3 | P10: CISO + Head of IT Security | R10: CISO + CIO (per Mgmt Review) | Z10: BFS-RISK-2026-0001,0002,0006,0029,0030 | AA10: TBD | AC10: Circular 1048 §3.4 | AD10: Req 6.3.3 | AE10: NPC advisories | AF10: ID.RA-02,03; DE.AE-07 | AH10: 46113 | AI10: 46478 | AJ10: Annual | AK10: v1.0 Apr-2026 — Initial SoA
A11: A.5.8 | B11: Information security in project management | C11: Applicable | D11: Security must be integrated into all BFS projects from inception, not retrofitted. SSDLC governance per BFS-ISP-016 covers application projects. The forthcoming BFS-ISP-027 will provide broader project management security framework covering non-application projects. | E11: BFS-ISP-016 (SSDLC); BFS-ISP-027 (forthcoming) | F11: A.5 Organizational | G11: Preventive | H11: Confidentiality, Integrity, Availability | I11: IDENTIFY, PROTECT | J11: Governance | K11: Governance and Ecosystem, Protection | L11: Partially Implemented | M11: 2 | O11: 2026-Q4 / 2027-Q1 | P11: CISO + Head of PMO | R11: CISO + CIO (per Mgmt Review) | Z11: BFS-RISK-2026-0026 | AB11: See Implementation Notes | AF11: GV.SC-05; ID.RA-09 | AH11: 46113 | AI11: 46478 | AJ11: Annual | AK11: v1.0 Apr-2026 — Initial SoA
A12: A.5.9 | B12: Inventory of information and other associated assets | C12: Applicable | D12: Foundational asset inventory is implemented through BFS-ISP-001 (Enterprise Asset Inventory) covering hardware, infrastructure, and physical assets, and BFS-ISP-002 (Software Asset Inventory) covering all software including SaaS, libraries, containers, and AI/ML models. Inventories are continuously maintained. | E12: BFS-ISP-001; BFS-ISP-002; BFS-ISP-016 (Application Inventory) | F12: A.5 Organizational | G12: Preventive | H12: Confidentiality, Integrity, Availability | I12: IDENTIFY, PROTECT | J12: Asset management | K12: Governance and Ecosystem, Protection | L12: Implemented | M12: 3 | P12: CIO + CISO | R12: CISO + CIO (per Mgmt Review) | Z12: BFS-RISK-2026-0011,0043 | AA12: TBD | AD12: Req 9.5 | AF12: ID.AM-01,02,03,04,05 | AH12: 46113 | AI12: 46478 | AJ12: Annual | AK12: v1.0 Apr-2026 — Initial SoA
A13: A.5.10 | B13: Acceptable use of information and other associated assets | C13: Applicable | D13: Acceptable use rules govern how BFS personnel use BFS-issued devices, networks, applications, and information assets. Currently addressed through fragmented references in multiple BFS-ISP policies; consolidated comprehensive Acceptable Use Policy is the highest-priority gap closure. | E13: BFS-ISP-020 (forthcoming); references in BFS-ISP-009, BFS-ISP-014 | F13: A.5 Organizational | G13: Preventive | H13: Confidentiality, Integrity, Availability | I13: PROTECT | J13: Asset management, Information protection | K13: Governance and Ecosystem, Protection | L13: Planned | M13: 1 | O13: 2026-Q4 / 2027-Q1 | P13: CISO + DPO | R13: CISO + CIO (per Mgmt Review) | Z13: BFS-RISK-2026-0009,0011,0029,0030 | AB13: See Implementation Notes | AC13: Circular 1140 §V.D | AD13: Req 7.1; 9.4 | AE13: RA 10173 §11 | AF13: GV.PO-01; PR.DS-01 | AH13: 46113 | AI13: 46478 | AJ13: Annual | AK13: v1.0 Apr-2026 — Initial SoA
A14: A.5.11 | B14: Return of assets | C14: Applicable | D14: Returning BFS assets at the end of employment, contract, or assignment is a foundational HR security control. To be addressed comprehensively in the forthcoming BFS-ISP-021 (HR Security Policy) covering pre-employment, during employment, and termination/change phases. | E14: BFS-ISP-021 (forthcoming) | F14: A.5 Organizational | G14: Preventive | H14: Confidentiality, Integrity, Availability | I14: PROTECT | J14: Asset management | K14: Protection | L14: Planned | M14: 1 | O14: 2026-Q4 / 2027-Q1 | P14: CIO + CISO + CHRO | R14: CISO + CIO (per Mgmt Review) | Z14: BFS-RISK-2026-0012 | AB14: See Implementation Notes | AF14: ID.AM-02; PR.AA-04 | AH14: 46113 | AI14: 46478 | AJ14: Annual | AK14: v1.0 Apr-2026 — Initial SoA
A15: A.5.12 | B15: Classification of information | C15: Applicable | D15: Information classification scheme is fundamental to applying proportionate controls. BFS uses a 4-tier classification: PUBLIC / INTERNAL / CONFIDENTIAL / RESTRICTED. Classification determines handling requirements, encryption obligations, retention, and access governance. | E15: BFS-ISP-003 §5.2; classification labels in document templates | F15: A.5 Organizational | G15: Preventive | H15: Confidentiality, Integrity, Availability | I15: IDENTIFY, PROTECT | J15: Information protection | K15: Protection, Defence | L15: Implemented | M15: 3 | P15: CISO + DPO | R15: CISO + CIO (per Mgmt Review) | Z15: BFS-RISK-2026-0011,0020,0038,0043 | AA15: TBD | AD15: Req 3.5; 7.1 | AE15: RA 10173 §11; NPC Circ 16-01 | AF15: ID.AM-05,07; GV.OC-01 | AH15: 46113 | AI15: 46478 | AJ15: Annual | AK15: v1.0 Apr-2026 — Initial SoA
A16: A.5.13 | B16: Labelling of information | C16: Applicable | D16: Information labelling implements the classification scheme operationally. All BFS documents bear classification labels in headers/footers; emails labeled per classification; data systems labeled at storage and processing layer; metadata-driven labelling for structured data. | E16: BFS-ISP-003 §5.2; document templates; data tagging | F16: A.5 Organizational | G16: Preventive | H16: Confidentiality, Integrity, Availability | I16: PROTECT | J16: Information protection | K16: Protection, Defence | L16: Partially Implemented | M16: 2 | O16: 2026-Q4 / 2027-Q1 | P16: CISO + DPO | R16: CISO + CIO (per Mgmt Review) | Z16: BFS-RISK-2026-0011,0020,0038 | AB16: See Implementation Notes | AE16: RA 10173 §11 | AF16: PR.DS-02; PR.AA-06 | AH16: 46113 | AI16: 46478 | AJ16: Annual | AK16: v1.0 Apr-2026 — Initial SoA
A17: A.5.14 | B17: Information transfer | C17: Applicable | D17: Information transfer covers internal and external transfer of information across networks, channels, and media. Includes secure email, file transfer, removable media, and cross-border transfers. Forthcoming BFS-ISP-024 will consolidate currently fragmented controls. | E17: BFS-ISP-024 (forthcoming); BFS-ISP-009; BFS-ISP-003 | F17: A.5 Organizational | G17: Preventive | H17: Confidentiality, Integrity, Availability | I17: PROTECT | J17: Information protection | K17: Protection | L17: Partially Implemented | M17: 2 | O17: 2026-Q4 / 2027-Q1 | P17: CISO + DPO | R17: CISO + CIO (per Mgmt Review) | Z17: BFS-RISK-2026-0009,0011,0038 | AB17: See Implementation Notes | AD17: Req 9.4; 9.5 | AE17: RA 10173 §11 | AF17: PR.DS-02,11 | AH17: 46113 | AI17: 46478 | AJ17: Annual | AK17: v1.0 Apr-2026 — Initial SoA
A18: A.5.15 | B18: Access control | C18: Applicable | D18: Access control is core to information security. BFS implements least-privilege, need-to-know, role-based access control, with progressive movement toward Zero Trust architecture. Comprehensive operational coverage through BFS-ISP-006. | E18: BFS-ISP-006; BFS-ISP-005 | F18: A.5 Organizational | G18: Preventive | H18: Confidentiality, Integrity, Availability | I18: PROTECT | J18: Identity and access management | K18: Protection | L18: Implemented | M18: 3 | P18: CISO + Head of IAM | R18: CISO + CIO (per Mgmt Review) | Z18: BFS-RISK-2026-0004,0010,0042 | AA18: TBD | AC18: Circular 1140 §V.B; Circular 1048 §3.3 | AD18: Req 7 | AF18: PR.AA-01,02,03,04,05 | AH18: 46113 | AI18: 46478 | AJ18: Annual | AK18: v1.0 Apr-2026 — Initial SoA
A19: A.5.16 | B19: Identity management | C19: Applicable | D19: Identity lifecycle management from provisioning through deprovisioning, with strong authentication, identity attestation, and reconciliation against authoritative HR source. Implemented through BFS-ISP-005 with PAM, IdP, and identity governance. | E19: BFS-ISP-005 | F19: A.5 Organizational | G19: Preventive | H19: Confidentiality, Integrity, Availability | I19: PROTECT | J19: Identity and access management | K19: Protection | L19: Implemented | M19: 3 | P19: CISO + Head of IAM | R19: CISO + CIO (per Mgmt Review) | Z19: BFS-RISK-2026-0004,0010,0012,0042 | AA19: TBD | AD19: Req 7.2; 8.1 | AF19: PR.AA-01,02,03 | AH19: 46113 | AI19: 46478 | AJ19: Annual | AK19: v1.0 Apr-2026 — Initial SoA
A20: A.5.17 | B20: Authentication information | C20: Applicable | D20: Protection of authentication information (passwords, tokens, certificates, biometric templates) from unauthorized disclosure. MFA mandated for all administrative and remote access; passwords managed per BFS standards; secrets management through enterprise PAM and secrets vaults. | E20: BFS-ISP-005 §5.3; BFS-ISP-006 | F20: A.5 Organizational | G20: Preventive | H20: Confidentiality, Integrity, Availability | I20: PROTECT | J20: Identity and access management | K20: Protection | L20: Implemented | M20: 3 | P20: CISO + Head of IAM | R20: CISO + CIO (per Mgmt Review) | Z20: BFS-RISK-2026-0004,0010,0042 | AA20: TBD | AD20: Req 8.3 | AF20: PR.AA-01,02,03 | AH20: 46113 | AI20: 46478 | AJ20: Annual | AK20: v1.0 Apr-2026 — Initial SoA
A21: A.5.18 | B21: Access rights | C21: Applicable | D21: Access rights provisioning, modification, periodic review, and termination. Quarterly access reviews for TIER 1 systems; annual reviews for all systems; immediate revocation on termination/role change. Implemented through BFS-ISP-005 §5.5 and BFS-ISP-006. | E21: BFS-ISP-005 §5.5; BFS-ISP-006 | F21: A.5 Organizational | G21: Preventive | H21: Confidentiality, Integrity, Availability | I21: PROTECT | J21: Identity and access management | K21: Protection | L21: Implemented | M21: 3 | P21: CISO + Head of IAM | R21: CISO + CIO (per Mgmt Review) | Z21: BFS-RISK-2026-0010,0012 | AA21: TBD | AD21: Req 7.2.5; 8.2.6 | AE21: RA 10173 §16(e) | AF21: PR.AA-05 | AH21: 46113 | AI21: 46478 | AJ21: Annual | AK21: v1.0 Apr-2026 — Initial SoA
A22: A.5.19 | B22: Information security in supplier relationships | C22: Applicable | D22: Comprehensive supplier security framework including pre-engagement due diligence, contractual security obligations, ongoing monitoring, and offboarding. BFS-ISP-015 implements four-tier supplier classification (TIER 1 CRITICAL through TIER 4 LOW) with calibrated controls for each tier. | E22: BFS-ISP-015 | F22: A.5 Organizational | G22: Preventive | H22: Confidentiality, Integrity, Availability | I22: IDENTIFY, PROTECT | J22: Supplier relationships security | K22: Governance and Ecosystem, Protection | L22: Implemented | M22: 3 | P22: CISO + Head of Vendor Management | R22: CISO + CIO (per Mgmt Review) | Z22: BFS-RISK-2026-0014,0015,0017,0018 | AA22: TBD | AC22: Circular 1140 §V.E; Circular 1144 (Outsourcing) | AE22: RA 10173 §16(f) | AF22: GV.SC-04,05,06,07 | AH22: 46113 | AI22: 46478 | AJ22: Annual | AK22: v1.0 Apr-2026 — Initial SoA
A23: A.5.20 | B23: Addressing information security within supplier agreements | C23: Applicable | D23: Standard Security Schedule and Data Processing Agreement (DPA) annexes for all supplier contracts. Specific clauses for incident notification SLAs, audit rights, data protection, encryption requirements, security testing, and offboarding obligations. | E23: BFS-ISP-015 §5.4; Legal Counsel templates | F23: A.5 Organizational | G23: Preventive | H23: Confidentiality, Integrity, Availability | I23: IDENTIFY, PROTECT | J23: Supplier relationships security | K23: Governance and Ecosystem, Protection | L23: Implemented | M23: 3 | P23: CISO + Head of Vendor Management + Legal | R23: CISO + CIO (per Mgmt Review) | Z23: BFS-RISK-2026-0014,0015,0017 | AA23: TBD | AC23: Circular 1140 §V.E | AD23: Req 12.8 | AE23: RA 10173 §16(f); §21 | AF23: GV.SC-05,07 | AH23: 46113 | AI23: 46478 | AJ23: Annual | AK23: v1.0 Apr-2026 — Initial SoA
A24: A.5.21 | B24: Managing information security in the ICT supply chain | C24: Applicable | D24: ICT supply chain risk addressed through Software Asset Inventory (BFS-ISP-002), SBOM requirements for TIER 1 software (BFS-ISP-016), Software Composition Analysis in CI/CD pipeline, and cloud service provider governance. Critical post-Log4Shell, SolarWinds, MOVEit lessons learned. | E24: BFS-ISP-002; BFS-ISP-015; BFS-ISP-016 §5.6.3 | F24: A.5 Organizational | G24: Preventive | H24: Confidentiality, Integrity, Availability | I24: IDENTIFY, PROTECT | J24: Supplier relationships security, System and network security | K24: Governance and Ecosystem, Protection | L24: Implemented | M24: 3 | P24: CISO + Head of Vendor Management | R24: CISO + CIO (per Mgmt Review) | Z24: BFS-RISK-2026-0006,0014,0015,0017 | AA24: TBD | AE24: RA 10173 §16(f) | AF24: GV.SC-07 | AH24: 46113 | AI24: 46478 | AJ24: Annual | AK24: v1.0 Apr-2026 — Initial SoA
A25: A.5.22 | B25: Monitoring, review and change management of supplier services | C25: Applicable | D25: Continuous monitoring of supplier service performance and security posture. Annual Vendor Risk Assessments for TIER 1/2; supplier change notifications required per contract; breach of supplier security obligations triggers remediation or contract termination. | E25: BFS-ISP-015 §5.6 | F25: A.5 Organizational | G25: Preventive | H25: Confidentiality, Integrity, Availability | I25: IDENTIFY, PROTECT | J25: Supplier relationships security | K25: Governance and Ecosystem, Protection | L25: Implemented | M25: 3 | P25: CISO + Head of Vendor Management | R25: CISO + CIO (per Mgmt Review) | Z25: BFS-RISK-2026-0014,0015,0017 | AA25: TBD | AC25: Circular 1140 §V.E; Circular 1144 | AD25: Req 12.8 | AE25: RA 10173 §16(f) | AF25: GV.SC-09,10 | AH25: 46113 | AI25: 46478 | AJ25: Annual | AK25: v1.0 Apr-2026 — Initial SoA
A26: A.5.23 | B26: Information security for use of cloud services | C26: Applicable | D26: Cloud security governance covering BFS's AWS environment and SaaS providers. Shared responsibility model documented; cloud-specific controls implemented; cloud penetration testing per BFS-ISP-018 §5.10.5; cloud configuration governance via Cloud Security Posture Management. | E26: BFS-ISP-006 (cloud access); BFS-ISP-015 (CSP as TIER 1); BFS-ISP-018 | F26: A.5 Organizational | G26: Preventive | H26: Confidentiality, Integrity, Availability | I26: PROTECT | J26: Supplier relationships security | K26: Governance and Ecosystem, Protection | L26: Implemented | M26: 3 | P26: CISO + Head of Cloud Engineering | R26: CISO + CIO (per Mgmt Review) | Z26: BFS-RISK-2026-0014,0016,0041,0042,0043 | AA26: TBD | AF26: GV.SC-07,10 | AH26: 46113 | AI26: 46478 | AJ26: Annual | AK26: v1.0 Apr-2026 — Initial SoA
A27: A.5.24 | B27: Information security incident management planning and preparation | C27: Applicable | D27: Comprehensive incident response framework with 4-severity classification, 24/7 SOC, 19 documented playbooks (PB-001 through PB-019), formal IR Team structure, retainer relationships with external IR firms. | E27: BFS-ISP-017 §4 and §5.3 | F27: A.5 Organizational | G27: Preventive / Corrective | H27: Confidentiality, Integrity, Availability | I27: RESPOND, RECOVER | J27: Governance, Information security event management | K27: Defence, Resilience | L27: Implemented | M27: 3 | P27: CISO + CIO | R27: CISO + CIO (per Mgmt Review) | Z27: BFS-RISK-2026-0024,0026,0044,0045 | AA27: TBD | AC27: Circular 1140 §VI | AD27: Req 12.10 | AE27: RA 10173 §20(f) | AF27: RS.MA-01,02,03 | AH27: 46113 | AI27: 46478 | AJ27: Annual | AK27: v1.0 Apr-2026 — Initial SoA
A28: A.5.25 | B28: Assessment and decision on information security events | C28: Applicable | D28: SOC triage process for raw security events into incidents per defined criteria. Severity classification workflow with documented escalation thresholds. False positive vs. true positive determination through structured analysis. | E28: BFS-ISP-017 §5.4 | F28: A.5 Organizational | G28: Preventive / Detective / Corrective | H28: Confidentiality, Integrity, Availability | I28: DETECT, RESPOND | J28: Information security event management | K28: Defence | L28: Implemented | M28: 3 | P28: CISO + Head of IT Security | R28: CISO + CIO (per Mgmt Review) | Z28: BFS-RISK-2026-0024,0044 | AA28: TBD | AC28: Circular 1140 §VI; Circular 1048 §3.5 | AD28: Req 12.10 | AE28: RA 10173 §20(f) | AF28: DE.AE-02,03,04,05,06,07,08; RS.AN-01 | AH28: 46113 | AI28: 46478 | AJ28: Annual | AK28: v1.0 Apr-2026 — Initial SoA
A29: A.5.26 | B29: Response to information security incidents | C29: Applicable | D29: Structured response workflow: Detection → Triage → Containment → Eradication → Recovery → Lessons Learned. Documented playbooks for 19 incident scenarios. Incident Commander role; out-of-band communication channels; legal/regulatory coordination. | E29: BFS-ISP-017 §5.5 and §6 | F29: A.5 Organizational | G29: Corrective | H29: Confidentiality, Integrity, Availability | I29: RESPOND, RECOVER | J29: Information security event management | K29: Defence, Resilience | L29: Implemented | M29: 3 | P29: CISO + Head of IT Security | R29: CISO + CIO (per Mgmt Review) | Z29: BFS-RISK-2026-0001,0024 | AA29: TBD | AC29: Circular 1140 §VI | AD29: Req 12.10 | AE29: RA 10173 §20(f) | AF29: RS.MA-04,05; RS.AN-06; RS.MI-01,02 | AH29: 46113 | AI29: 46478 | AJ29: Annual | AK29: v1.0 Apr-2026 — Initial SoA
A30: A.5.27 | B30: Learning from information security incidents | C30: Applicable | D30: Mandatory Post-Incident Review (PIR) for all CRITICAL/HIGH incidents within 30 days. Root cause analysis, lessons learned, control improvements, playbook refinements, awareness reinforcement. PIR outputs feed continuous improvement of the BFS-ISP series. | E30: BFS-ISP-017 §5.8 | F30: A.5 Organizational | G30: Preventive / Detective | H30: Confidentiality, Integrity, Availability | I30: IDENTIFY, PROTECT | J30: Information security event management | K30: Defence, Resilience | L30: Implemented | M30: 3 | P30: CISO | R30: CISO + CIO (per Mgmt Review) | Z30: BFS-RISK-2026-0024,0026 | AA30: TBD | AF30: ID.IM-01,02,03,04; RS.AN-08 | AH30: 46113 | AI30: 46478 | AJ30: Annual | AK30: v1.0 Apr-2026 — Initial SoA
A31: A.5.28 | B31: Collection of evidence | C31: Applicable | D31: Forensic evidence preservation procedures supporting law enforcement coordination, civil litigation, and regulatory examinations. Chain of custody requirements; forensic imaging procedures; legal hold management; admissibility-aware evidence handling. | E31: BFS-ISP-017 §5.6; Legal Counsel coordination | F31: A.5 Organizational | G31: Corrective | H31: Confidentiality, Integrity, Availability | I31: RESPOND | J31: Information security event management | K31: Defence | L31: Implemented | M31: 3 | P31: CISO + Legal | R31: CISO + CIO (per Mgmt Review) | Z31: BFS-RISK-2026-0024 | AA31: TBD | AF31: RS.AN-06,07; PR.IR-01 | AH31: 46113 | AI31: 46478 | AJ31: Annual | AK31: v1.0 Apr-2026 — Initial SoA
A32: A.5.29 | B32: Information security during disruption | C32: Applicable | D32: Information security must continue during operational disruptions, not be suspended for expedience. BFS-ISP-011 establishes data recovery requirements; forthcoming BFS-ISP-011-BCP will provide comprehensive Business Continuity framework integrating with information security. | E32: BFS-ISP-011; BFS-ISP-011-BCP (forthcoming) | F32: A.5 Organizational | G32: Preventive / Corrective | H32: Confidentiality, Integrity, Availability | I32: PROTECT, RESPOND, RECOVER | J32: Continuity | K32: Protection, Resilience | L32: Partially Implemented | M32: 2 | O32: 2026-Q4 / 2027-Q1 | P32: CIO + Head of BCM | R32: CISO + CIO (per Mgmt Review) | Z32: BFS-RISK-2026-0024,0035,0044,0045 | AB32: See Implementation Notes | AC32: Circular 951 (BCM) | AD32: Req 12.10.1 | AF32: RC.RP-01,02,03,04,05,06; ID.IM-01,02,03,04 | AH32: 46113 | AI32: 46478 | AJ32: Annual | AK32: v1.0 Apr-2026 — Initial SoA
A33: A.5.30 | B33: ICT readiness for business continuity | C33: Applicable | D33: ICT-specific BCM requirements: tested DR procedures, RTO/RPO commitments per BFS-ISP-011, alternate processing arrangements, communication contingencies, ICT supplier dependency considerations. Forthcoming BFS-ISP-011-DRP will provide comprehensive DR plan. | E33: BFS-ISP-011; BFS-ISP-011-DRP (forthcoming) | F33: A.5 Organizational | G33: Preventive / Corrective | H33: Availability | I33: RESPOND, RECOVER | J33: Continuity | K33: Resilience | L33: Partially Implemented | M33: 2 | O33: 2026-Q4 / 2027-Q1 | P33: CIO + Head of BCM | R33: CISO + CIO (per Mgmt Review) | Z33: BFS-RISK-2026-0024,0044,0045 | AB33: See Implementation Notes | AC33: Circular 951 | AF33: RC.RP-01,02,03,04,05,06 | AH33: 46113 | AI33: 46478 | AJ33: Annual | AK33: v1.0 Apr-2026 — Initial SoA
A34: A.5.31 | B34: Legal, statutory, regulatory and contractual requirements | C34: Applicable | D34: BFS as a BSP-supervised institution operates within an extensive regulatory framework: BSP Circulars 1140/1048/982/144/808, RA 10173, RA 10175, RA 11765, RA 8791, PCI DSS v4.0, plus card scheme rules and SWIFT CSP. Comprehensive register and compliance program. | E34: BFS-ISP-026 (forthcoming); CCO function | F34: A.5 Organizational | G34: Preventive | H34: Confidentiality, Integrity, Availability | I34: IDENTIFY, PROTECT | J34: Legal and compliance | K34: Governance and Ecosystem | L34: Partially Implemented | M34: 2 | O34: 2026-Q4 / 2027-Q1 | P34: CCO + Legal | R34: CISO + CIO (per Mgmt Review) | Z34: BFS-RISK-2026-0019,0020,0021,0022,0023 | AB34: See Implementation Notes | AC34: Circular 1140 §II | AE34: RA 10173; RA 8791; RA 11765 | AF34: GV.OC-01,02,03,04,05; GV.RM-07 | AH34: 46113 | AI34: 46478 | AJ34: Annual | AK34: v1.0 Apr-2026 — Initial SoA
A35: A.5.32 | B35: Intellectual property rights | C35: Applicable | D35: BFS holds intellectual property (proprietary software, business processes, brand) and uses third-party intellectual property (licensed software, content). IP protection and license compliance are operational concerns. Software license management per BFS-ISP-002. | E35: BFS-ISP-002 (license compliance); BFS-ISP-026 | F35: A.5 Organizational | G35: Preventive | H35: Confidentiality, Integrity, Availability | I35: IDENTIFY, PROTECT | J35: Legal and compliance | K35: Governance and Ecosystem | L35: Partially Implemented | M35: 2 | O35: 2026-Q4 / 2027-Q1 | P35: CCO + Legal | R35: CISO + CIO (per Mgmt Review) | Z35: BFS-RISK-2026-0019,0028 | AB35: See Implementation Notes | AE35: Copyright Act | AF35: GV.OC-03,04,05 | AH35: 46113 | AI35: 46478 | AJ35: Annual | AK35: v1.0 Apr-2026 — Initial SoA
A36: A.5.33 | B36: Protection of records | C36: Applicable | D36: Records protection is mandatory for a regulated financial institution — records include transaction records, customer correspondence, audit logs, regulatory submissions, contracts. Retention periods per regulatory requirements; integrity protection; controlled disposal at end of retention. | E36: BFS-ISP-008 (audit logs); BFS-ISP-003 (data retention); BFS-ISMS-006 | F36: A.5 Organizational | G36: Preventive | H36: Confidentiality, Integrity, Availability | I36: PROTECT | J36: Information protection, Legal and compliance | K36: Protection, Governance and Ecosystem | L36: Implemented | M36: 3 | P36: DPO + CISO | R36: CISO + CIO (per Mgmt Review) | Z36: BFS-RISK-2026-0011,0028 | AA36: TBD | AE36: RA 10173 §11 | AF36: PR.DS-01,02; GV.OC-04 | AH36: 46113 | AI36: 46478 | AJ36: Annual | AK36: v1.0 Apr-2026 — Initial SoA
A37: A.5.34 | B37: Privacy and protection of PII | C37: Applicable | D37: RA 10173 (Data Privacy Act) is foundational regulatory requirement for BFS. Comprehensive PII protection through BFS-ISP-003, DPO function, Privacy Impact Assessments integrated into SSDLC, 72-hour NPC breach notification, data subject rights fulfillment. | E37: BFS-ISP-003; DPO function; BFS-ISP-017 §5.9.2 | F37: A.5 Organizational | G37: Preventive | H37: Confidentiality | I37: IDENTIFY, PROTECT | J37: Information protection, Legal and compliance | K37: Protection, Governance and Ecosystem | L37: Implemented | M37: 3 | P37: DPO | R37: CISO + CIO (per Mgmt Review) | Z37: BFS-RISK-2026-0020,0038,0039,0040 | AA37: TBD | AC37: Circular 1140 §V.D; Circular 1048 | AD37: Req 3 | AE37: RA 10173 §11; §16 | AF37: PR.DS-01,02,11; GV.OC-04 | AH37: 46113 | AI37: 46478 | AJ37: Annual | AK37: v1.0 Apr-2026 — Initial SoA
A38: A.5.35 | B38: Independent review of information security | C38: Applicable | D38: Internal audit function operates independently of operational management with reporting line to Board Audit & Risk Committee. Annual ISMS audits per BFS-ISMS-008. External penetration testing per BFS-ISP-018. ISO 27001 certification audit (planned) provides additional independence. | E38: BFS-ISMS-008; BFS-ISP-018 | F38: A.5 Organizational | G38: Preventive / Detective | H38: Confidentiality, Integrity, Availability | I38: IDENTIFY, PROTECT | J38: Information security assurance | K38: Governance and Ecosystem | L38: Implemented | M38: 3 | P38: CISO + Internal Audit | R38: CISO + CIO (per Mgmt Review) | Z38: BFS-RISK-2026-0022 | AA38: TBD | AF38: GV.OV-01,02,03; ID.IM-03 | AH38: 46113 | AI38: 46478 | AJ38: Annual | AK38: v1.0 Apr-2026 — Initial SoA
A39: A.5.36 | B39: Compliance with policies, rules and standards for information security | C39: Applicable | D39: Compliance with BFS information security policies is mandatory and monitored. Internal audit verifies compliance per BFS-ISMS-008; nonconformities tracked through BFS-ISMS-010 Corrective Action; KPI monitoring across BFS-ISP series; disciplinary framework per BFS-ISMS-001 §11. | E39: BFS-ISMS-008; BFS-ISMS-010; BFS-ISMS-001 §11 | F39: A.5 Organizational | G39: Preventive / Detective | H39: Confidentiality, Integrity, Availability | I39: IDENTIFY, PROTECT | J39: Legal and compliance, Information security assurance | K39: Governance and Ecosystem | L39: Implemented | M39: 3 | P39: CCO + Internal Audit | R39: CISO + CIO (per Mgmt Review) | Z39: BFS-RISK-2026-0019,0020,0021,0022,0023 | AA39: TBD | AE39: RA 10173 | AF39: GV.OV-01,02,03; GV.OC-03,04,05 | AH39: 46113 | AI39: 46478 | AJ39: Annual | AK39: v1.0 Apr-2026 — Initial SoA
A40: A.5.37 | B40: Documented operating procedures | C40: Applicable | D40: Operating procedures documented for all significant security activities. Document control governance per BFS-ISMS-006. Procedures referenced in each BFS-ISP policy §6 (Procedures). Operational runbooks maintained at TIER 4 level supporting day-to-day execution. | E40: BFS-ISMS-006; procedures in each BFS-ISP §6 | F40: A.5 Organizational | G40: Preventive / Corrective | H40: Confidentiality, Integrity, Availability | I40: PROTECT, RESPOND, RECOVER | J40: Governance, Asset management, Physical security, System and network security, Application security, Identity and access management, Threat and vulnerability management, Continuity, Information security event management, Information protection, Information security assurance | K40: Governance and Ecosystem, Protection, Defence, Resilience | L40: Implemented | M40: 3 | P40: CIO + CISO | R40: CISO + CIO (per Mgmt Review) | Z40: BFS-RISK-2026-0024,0026 | AA40: TBD | AF40: PR.IR-01,02,03,04; RS.MA-01,02 | AH40: 46113 | AI40: 46478 | AJ40: Annual | AK40: v1.0 Apr-2026 — Initial SoA
A41: A.6.1 | B41: Screening | C41: Applicable | D41: Pre-employment screening is critical for a financial institution. BFS conducts background checks proportionate to role sensitivity — enhanced screening for roles with privileged access, financial transaction authority, or PII access. Aligns with BSP fit-and-proper requirements for material roles. | E41: BFS-ISP-021 (forthcoming); HR processes | F41: A.6 People | G41: Preventive | H41: Confidentiality, Integrity, Availability | I41: PROTECT | J41: Human resource security | K41: Governance and Ecosystem, Protection | L41: Planned | M41: 1 | O41: 2026-Q4 / 2027-Q1 | P41: CHRO + CISO | R41: CISO + CIO (per Mgmt Review) | Z41: BFS-RISK-2026-0009,0010,0012 | AB41: See Implementation Notes | AC41: Circular 1140 §V.C | AD41: Req 12.7 | AE41: RA 10173 §16(d) | AF41: PR.AT-01,02; GV.RR-03,04 | AH41: 46113 | AI41: 46478 | AJ41: Annual | AK41: v1.0 Apr-2026 — Initial SoA
...

Sheet Dashboard
A1: SOA COVERAGE DASHBOARD
A3: Implementation Status Summary | F3: Coverage by Theme
A4: Status | B4: Count | C4: % of Total | D4: Color | F4: Theme | G4: Count | H4: % of Total
A5: Implemented | B5: =COUNTIF('SoA Register'!L:L,"Implemented") -> 61 | C5: =B5/SUM($B$5:$B$8) -> 0.65591398 | D5: ███ | F5: A.5 Organizational | G5: =COUNTIF('SoA Register'!F:F,"A.5 Organizational") -> 37 | H5: =G5/SUM($G$5:$G$8) -> 0.39784946
A6: Partially Implemented | B6: =COUNTIF('SoA Register'!L:L,"Partially Implemented") -> 18 | C6: =B6/SUM($B$5:$B$8) -> 0.19354839 | D6: ███ | F6: A.6 People | G6: =COUNTIF('SoA Register'!F:F,"A.6 People") -> 8 | H6: =G6/SUM($G$5:$G$8) -> 0.086021505
A7: Planned | B7: =COUNTIF('SoA Register'!L:L,"Planned") -> 14 | C7: =B7/SUM($B$5:$B$8) -> 0.15053763 | D7: ███ | F7: A.7 Physical | G7: =COUNTIF('SoA Register'!F:F,"A.7 Physical") -> 14 | H7: =G7/SUM($G$5:$G$8) -> 0.15053763
A8: Not Implemented | B8: =COUNTIF('SoA Register'!L:L,"Not Implemented") -> 0 | C8: =B8/SUM($B$5:$B$8) -> 0 | D8: ███ | F8: A.8 Technological | G8: =COUNTIF('SoA Register'!F:F,"A.8 Technological") -> 34 | H8: =G8/SUM($G$5:$G$8) -> 0.3655914
A9: TOTAL | B9: =SUM(B5:B8) -> 93 | C9: 100.0% | F9: TOTAL | G9: =SUM(G5:G8) -> 93 | H9: 100.0%
A12: Applicability Summary | F12: Maturity Level Distribution
A13: Decision | B13: Count | C13: % of Total | F13: Maturity | G13: Count | H13: % of Applicable
A14: Applicable | B14: =COUNTIF('SoA Register'!C:C,"Applicable") -> 93 | C14: =B14/SUM($B$14:$B$15) -> 1 | F14: Level 3 — Defined | G14: =COUNTIF('SoA Register'!M:M,3) -> 61 | H14: =G14/COUNTIF('SoA Register'!C:C,"Applicable") -> 0.65591398
A15: Not Applicable | B15: =COUNTIF('SoA Register'!C:C,"Not Applicable") -> 0 | C15: =B15/SUM($B$14:$B$15) -> 0 | F15: Level 2 — Managed | G15: =COUNTIF('SoA Register'!M:M,2) -> 18 | H15: =G15/COUNTIF('SoA Register'!C:C,"Applicable") -> 0.19354839
F16: Level 1 — Initial | G16: =COUNTIF('SoA Register'!M:M,1) -> 14 | H16: =G16/COUNTIF('SoA Register'!C:C,"Applicable") -> 0.15053763
F17: Level 0 — Not Implemented | G17: =COUNTIF('SoA Register'!M:M,0) -> 0 | H17: =G17/COUNTIF('SoA Register'!C:C,"Applicable") -> 0
A20: Implementation Status by Theme
A21: Theme | B21: Implemented | C21: Partially Impl. | D21: Planned | E21: Not Impl. | F21: Theme Total
A22: A.5 Organizational | B22: =COUNTIFS('SoA Register'!F:F,"A.5 Organizational",'SoA Register'!L:L,"Implemented") -> 27 | C22: =COUNTIFS('SoA Register'!F:F,"A.5 Organizational",'SoA Register'!L:L,"Partially Implemented") -> 8 | D22: =COUNTIFS('SoA Register'!F:F,"A.5 Organizational",'SoA Register'!L:L,"Planned") -> 2 | E22: =COUNTIFS('SoA Register'!F:F,"A.5 Organizational",'SoA Register'!L:L,"Not Implemented") -> 0 | F22: =SUM(B22:E22) -> 37
A23: A.6 People | B23: =COUNTIFS('SoA Register'!F:F,"A.6 People",'SoA Register'!L:L,"Implemented") -> 4 | C23: =COUNTIFS('SoA Register'!F:F,"A.6 People",'SoA Register'!L:L,"Partially Implemented") -> 0 | D23: =COUNTIFS('SoA Register'!F:F,"A.6 People",'SoA Register'!L:L,"Planned") -> 4 | E23: =COUNTIFS('SoA Register'!F:F,"A.6 People",'SoA Register'!L:L,"Not Implemented") -> 0 | F23: =SUM(B23:E23) -> 8
A24: A.7 Physical | B24: =COUNTIFS('SoA Register'!F:F,"A.7 Physical",'SoA Register'!L:L,"Implemented") -> 2 | C24: =COUNTIFS('SoA Register'!F:F,"A.7 Physical",'SoA Register'!L:L,"Partially Implemented") -> 4 | D24: =COUNTIFS('SoA Register'!F:F,"A.7 Physical",'SoA Register'!L:L,"Planned") -> 8 | E24: =COUNTIFS('SoA Register'!F:F,"A.7 Physical",'SoA Register'!L:L,"Not Implemented") -> 0 | F24: =SUM(B24:E24) -> 14
A25: A.8 Technological | B25: =COUNTIFS('SoA Register'!F:F,"A.8 Technological",'SoA Register'!L:L,"Implemented") -> 28 | C25: =COUNTIFS('SoA Register'!F:F,"A.8 Technological",'SoA Register'!L:L,"Partially Implemented") -> 6 | D25: =COUNTIFS('SoA Register'!F:F,"A.8 Technological",'SoA Register'!L:L,"Planned") -> 0 | E25: =COUNTIFS('SoA Register'!F:F,"A.8 Technological",'SoA Register'!L:L,"Not Implemented") -> 0 | F25: =SUM(B25:E25) -> 34
A26: TOTAL | B26: =SUM(B22:B25) -> 61 | C26: =SUM(C22:C25) -> 18 | D26: =SUM(D22:D25) -> 14 | E26: =SUM(E22:E25) -> 0 | F26: =SUM(F22:F25) -> 93

Sheet Coverage Analysis
A1: ANNEX A COMPARISON EVIDENCE — Clause 6.1.3(c)
A2: Per BFS-ISMS-003 §7.2 — Documents Risk Register entries that drove control selection (auditor evidence for omission check)
A4: Ctrl ID | B4: Control Title | C4: Theme | D4: Risks Mitigated | E4: Coverage Notes
A5: A.5.1 | B5: Policies for information security | C5: A.5 Organizational | D5: BFS-RISK-2025-0022 | E5: Risk-driven; specific Risk Register entries
A6: A.5.2 | B6: Information security roles and responsibilities | C6: A.5 Organizational | E6: ISO 27001 baseline; BSP regulatory expectation
A7: A.5.3 | B7: Segregation of duties | C7: A.5 Organizational | E7: ISO 27001 baseline; BSP regulatory expectation
A8: A.5.4 | B8: Management responsibilities | C8: A.5 Organizational | E8: ISO 27001 baseline; BSP regulatory expectation
A9: A.5.5 | B9: Contact with authorities | C9: A.5 Organizational | E9: ISO 27001 baseline; BSP regulatory expectation
A10: A.5.6 | B10: Contact with special interest groups | C10: A.5 Organizational | D10: BFS-RISK-2025-0001,0002,0006 | E10: Risk-driven; specific Risk Register entries
A11: A.5.7 | B11: Threat intelligence | C11: A.5 Organizational | D11: BFS-RISK-2025-0001,0002,0006,0029,0030 | E11: Risk-driven; specific Risk Register entries
A12: A.5.8 | B12: Information security in project management | C12: A.5 Organizational | D12: BFS-RISK-2025-0026 | E12: Risk-driven; specific Risk Register entries
A13: A.5.9 | B13: Inventory of information and other associated assets | C13: A.5 Organizational | D13: BFS-RISK-2025-0011,0043 | E13: Risk-driven; specific Risk Register entries
A14: A.5.10 | B14: Acceptable use of information and other associated assets | C14: A.5 Organizational | D14: BFS-RISK-2025-0009,0011,0029,0030 | E14: Risk-driven; specific Risk Register entries
A15: A.5.11 | B15: Return of assets | C15: A.5 Organizational | D15: BFS-RISK-2025-0012 | E15: Risk-driven; specific Risk Register entries
A16: A.5.12 | B16: Classification of information | C16: A.5 Organizational | D16: BFS-RISK-2025-0011,0020,0038,0043 | E16: Risk-driven; specific Risk Register entries
A17: A.5.13 | B17: Labelling of information | C17: A.5 Organizational | D17: BFS-RISK-2025-0011,0020,0038 | E17: Risk-driven; specific Risk Register entries
A18: A.5.14 | B18: Information transfer | C18: A.5 Organizational | D18: BFS-RISK-2025-0009,0011,0038 | E18: Risk-driven; specific Risk Register entries
A19: A.5.15 | B19: Access control | C19: A.5 Organizational | D19: BFS-RISK-2025-0004,0010,0042 | E19: Risk-driven; specific Risk Register entries
A20: A.5.16 | B20: Identity management | C20: A.5 Organizational | D20: BFS-RISK-2025-0004,0010,0012,0042 | E20: Risk-driven; specific Risk Register entries
A21: A.5.17 | B21: Authentication information | C21: A.5 Organizational | D21: BFS-RISK-2025-0004,0010,0042 | E21: Risk-driven; specific Risk Register entries
... A97: A.8.34 | B97: Protection of information systems during audit testing | C97: A.8 Technological | D97: BFS-RISK-2025-0028 | E97: Risk-driven; specific Risk Register entries

Sheet Audit Trail
A1: SOA CHANGE LOG
A2: Material changes to applicability decisions, justifications, or implementation status. Must be reflected in next BFS-ISMS-004 .docx version.
A4: Date | B4: Ctrl ID | C4: Change Type | D4: Description of Change | E4: Driver / Rationale | F4: Approver
A5: 46127 | B5: All | C5: Initial Release | D5: BFS-ISMS-004 SoA v1.0 published; all 93 Annex A controls assessed; all declared Applicable. | E5: Initial ISMS implementation; certification preparation. | F5: CISO + CIO + CRO + Board AC
A6: 46127 | B6: All | C6: Working Register Created | D6: BFS-ISMS-004 Working Register v1.0 derived from .docx. Adds 30 operational tracking columns. | E6: Operational management of SoA; audit preparation. | F6: CISO

Sheet Reference & Schema
A1: SOA WORKING REGISTER — COLUMN DEFINITIONS & SCHEMA
A3: Column Definitions
A4: Column | B4: Source | C4: Definition & Purpose
A5: Ctrl ID | B5: BFS-ISMS-004 / ISO 27001:2022 Annex A | C5: Annex A control identifier. Primary key for cross-reference to the standard.
A6: Control Title | B6: BFS-ISMS-004 / ISO 27001:2022 Annex A | C6: Official ISO control title. Use for direct cross-reference to ISO/IEC 27002:2022 implementation guidance.
A7: Applicable? | B7: BFS-ISMS-004 (Authoritative) | C7: BFS's applicability determination per ISO 27001 Clause 6.1.3(d). Applicable / Not Applicable.
A8: Justification & BFS Implementation Context | B8: BFS-ISMS-004 (Authoritative) | C8: For Applicable: justification + brief implementation context. For Not Applicable: specific credible exclusion rationale.
A9: Primary Implementation Reference | B9: BFS-ISMS-004 (Authoritative) | C9: Primary BFS policy/procedure implementing the control. Updates here must propagate to BFS-ISMS-004 .docx.
A10: Control Theme | B10: ISO 27002:2022 | C10: A.5 Organizational / A.6 People / A.7 Physical / A.8 Technological.
A11: Control Type | B11: ISO 27002:2022 attribute | C11: Preventive / Detective / Corrective. Many controls combine types (e.g., Preventive + Detective).
A12: Information Security Properties | B12: ISO 27002:2022 attribute | C12: Which CIA dimensions the control protects: Confidentiality / Integrity / Availability.
A13: Cybersecurity Concept (NIST CSF) | B13: ISO 27002:2022 attribute | C13: Identify / Protect / Detect / Respond / Recover. Aligned to NIST Cybersecurity Framework functions.
A14: Operational Capability | B14: ISO 27002:2022 attribute | C14: Capability area: Governance / Asset_management / Information_protection / Identity_and_access_management / etc.
A15: Security Domain | B15: ISO 27002:2022 attribute | C15: Governance_and_Ecosystem / Protection / Defence / Resilience.
... A44: Remarks | B44: Operational | C44: General remarks parallel to Risk Register Remarks column.
A48: Implementation Status Definitions
A49: Status | B49: Maturity | C49: Definition
A50: Implemented | B50: 3 Defined | C50: Control fully implemented per defined policy/procedure. Evidence available. Operating consistently. Verified within last 12 months.
A51: Partially Implemented | B51: 2 Managed | C51: Control implementation in progress or partial. Some evidence available. May have gaps in scope or consistency. Target date documented for full implementation.
A52: Planned | B52: 1 Initial | C52: Control implementation planned but not yet operational. Target date documented. Compensating controls may apply.
A53: Not Implemented | B53: 0 None | C53: Control not implemented despite Applicable determination. Significant gap requiring CISO attention and risk treatment plan.
A56: ISO 27001:2022 Annex A Themes
A57: Theme | B57: Controls | C57: Description
A58: A.5 Organizational | B58: 37 (A.5.1-A.5.37) | C58: Governance, policies, accountability, supplier relationships, incident management, continuity, legal/compliance.
A59: A.6 People | B59: 8 (A.6.1-A.6.8) | C59: Personnel security, screening, training, agreements, disciplinary process, remote working, reporting.
A60: A.7 Physical | B60: 14 (A.7.1-A.7.14) | C60: Physical perimeters, entry controls, securing offices, monitoring, equipment placement, utilities, cabling, maintenance, off-premises assets, secure disposal.
A61: A.8 Technological | B61: 34 (A.8.1-A.8.34) | C61: Endpoint devices, access controls, identity management, authentication, capacity, malware, vulnerabilities, configuration, data masking, leakage, backup, redundancy, logging, monitoring, networks, cryptography, secure development, application security, code, change management.
